<?xml version="1.0" ?>
<!-- =================================================================================== -->
<!-- |    This document was autogenerated by xacro from wsg_50.urdf.xacro              | -->
<!-- |    EDITING THIS FILE BY HAND IS NOT RECOMMENDED                                 | -->
<!-- =================================================================================== -->
<robot name="wsg_50" xmlns:xacro="http://www.ros.org/wiki/xacro">
  <link name="wsg_50_palm_link">
    <inertial>
      <origin rpy="0 0 0" xyz="0 0 0"/>
      <mass value="1"/>
      <inertia ixx="0.01" ixy="0" ixz="0" iyy="0.01" iyz="0" izz="0.01"/>
    </inertial>
    <visual>
      <geometry>
        <mesh filename="package://schunk_description/meshes/wsg_50/palm.stl"/>
      </geometry>
    </visual>
    <collision>
      <geometry>
        <mesh filename="package://schunk_description/meshes/wsg_50/palm.stl"/>
      </geometry>
    </collision>
  </link>
  <joint name="wsg_50_finger_left_joint" type="prismatic">
    <origin rpy="3.1415 3.1415 0" xyz="0 -0.0719 0"/>
    <parent link="wsg_50_palm_link"/>
    <child link="wsg_50_finger_left_link"/>
    <axis xyz="0 1 0"/>
    <limit effort="10" lower="-0.001" upper="0.061" velocity="2.0"/>
  </joint>
  <link name="wsg_50_finger_left_link">
    <inertial>
      <origin rpy="0 0 0" xyz="0 0 0"/>
      <mass value="1"/>
      <inertia ixx="0.01" ixy="0" ixz="0" iyy="0.01" iyz="0" izz="0.01"/>
    </inertial>
    <visual>
      <geometry>
        <mesh filename="package://schunk_description/meshes/wsg_50/finger.stl"/>
      </geometry>
    </visual>
    <collision>
      <geometry>
        <mesh filename="package://schunk_description/meshes/wsg_50/finger.stl"/>
      </geometry>
    </collision>
  </link>
  <joint name="wsg_50_finger_right_joint" type="prismatic">
    <origin rpy="3.1415 0 0" xyz="0 -0.0719 0.0"/>
    <parent link="wsg_50_palm_link"/>
    <child link="wsg_50_finger_right_link"/>
    <axis xyz="0 -1 0"/>
    <mimic joint="wsg_50_finger_left_joint" multiplier="1" offset="0"/>
    <limit effort="10" lower="-0.001" upper="0.061" velocity="2.0"/>
  </joint>
  <link name="wsg_50_finger_right_link">
    <inertial>
      <origin rpy="0 0 0" xyz="0 0 0"/>
      <mass value="1"/>
      <inertia ixx="0.01" ixy="0" ixz="0" iyy="0.01" iyz="0" izz="0.01"/>
    </inertial>
    <visual>
      <geometry>
        <mesh filename="package://schunk_description/meshes/wsg_50/finger.stl"/>
      </geometry>
    </visual>
    <collision>
      <geometry>
        <mesh filename="package://schunk_description/meshes/wsg_50/finger.stl"/>
      </geometry>
    </collision>
  </link>
  <!-- extensions -->
  <transmission name="wsg_50_finger_left_trans">
    <type>transmission_interface/SimpleTransmission</type>
    <joint name="wsg_50_finger_left_joint"/>
    <actuator name="wsg_50_finger_left_motor">
      <hardwareInterface>EffortJointInterface</hardwareInterface>
      <mechanicalReduction>1</mechanicalReduction>
    </actuator>
  </transmission>
  <transmission name="wsg_50_finger_right_trans">
    <type>transmission_interface/SimpleTransmission</type>
    <joint name="wsg_50_finger_right_joint"/>
    <actuator name="wsg_50_finger_right_motor">
      <hardwareInterface>EffortJointInterface</hardwareInterface>
      <mechanicalReduction>1</mechanicalReduction>
    </actuator>
  </transmission>
</robot>
